Workbook

Sheet Dermatology
A1: (Do Not Modify) Provider Service | B1: (Do Not Modify) Row Checksum | C1: (Do Not Modify) Modified On | D1: Network Name | E1: Status | F1: VSS | G1: Availability | H1: Provider | I1: Notes (Provider) (Provider) | J1: Provider Identifier | K1: HPP | L1: Specialty | M1: Specialty Group (Specialty) (Specialty) | N1: Subservice Rollup | O1: Telehealth Available | P1: Care Site Phone Number | Q1: Care Site Fax (Caresite) (Care Site) | R1: Caresite | S1: Care Site Address | T1: Care Site City | U1: Care Site State | V1: Care Site Zip Code | W1: Organization / Group | X1: Created On | Y1: Deactivation Date | Z1: Coverage County | AA1: Catchment | AB1: HSRM | AC1: EPS | AD1: Compass_Display | AE1: Compass_Include | AF1: Compass_Office_Nickname | AG1: Compass_Referral_Fax | AH1: Compass_Medical_Records_Fax | AI1: Compass_Email | AJ1: Compass_HSRM_Status | AK1: Compass_EPS_Status | AL1: Compass_Accepting_Status | AM1: Compass_Preferred_Method | AN1: Compass_Internal_Notes | AO1: Compass_Referral_Comment_Notes | AP1: Compass_Tags | AQ1: Compass_Last_Verified | AR1: Compass_Verified_By | AS1: Compass_Update_Status | AT1: Compass_Update_Notes | AU1: Latitude | AV1: Longitude | AW1: Gecord_Status
A2: b5d793b2-7726-4425-ae68-3377951fbe2f | B2: Jy1sZRnl5gibAZT92a+pW7kHJy8O1VFRc0iOyBWi4sASY4d4du/teXgEc/Y1deY4GjwntIM5TZTI13uIiCegWA== | C2: 46152.198 | D2: CCN Region 2 | E2: Active | F2: No | G2: Accepting patients | H2: DERMATOLOGY SPEC OF GRAND RAPIDS PLLC | I2: No | J2: 1689306680 | K2: Unknown | L2: Dermatology | M2: Dermatology | O2: No | P2: 616-369-1600 | R2: DERMATOLOGY SPEC OF GRAND RAPIDS PLLC | S2: 1000 EAST PARIS AVE SE | T2: GRAND RAPIDS | U2: MI | V2: 49546-3691 | X2: 46152.031 | Z2: =_xlfn.XLOOKUP(VALUE(LEFT(V2,5)), 'MI Zip Codes'!A:A, 'MI Zip Codes'!B:B, "County Not Found") -> Kent | AA2: Battle Creek
A3: 6e280754-098f-41b3-beb7-9f29af42a2dd | B3: XA7mHnMZSQ8n3cqd9d39BIot/M5nWB0xbc3al+xQup7Kr3a12xYezpUGnipyaPD93LgT/a5ENSTSzTW5/3t0gA== | C3: 46169.613 | D3: CCN Region 2 | E3: Active | F3: No | G3: Accepting patients | H3: VISCONTI, MICHAEL | I3: No | J3: 1235767856 | K3: Unknown | L3: Dermatology | M3: Dermatology | O3: No | P3: 586-876-2345 | R3: DERMATOLOGY SPECIALISTS OF GRAND RAPIDS | S3: 1000 EAST PARIS AVE SE STE 104 | T3: GRAND RAPIDS | U3: MI | V3: 49546-3680 | W3: DERMATOLOGY SPECIALISTS OF GRAND RAPI | X3: 46169.446 | Z3: =_xlfn.XLOOKUP(VALUE(LEFT(V3,5)), 'MI Zip Codes'!A:A, 'MI Zip Codes'!B:B, "County Not Found") -> Kent | AA3: Battle Creek
A4: a00bf6c5-1987-4cb3-84a2-1057cd43edbc | B4: +iMknhY5w8iQp0WgTSZQTfC5M5eylIXFnmrhdcTT3SclrhGZ8Ncwz5ZMeQZUjoO3zNvMJ9OIPgSLJueZyw453A== | C4: 46010.322 | D4: CCN Region 2 | E4: Active | F4: No | G4: Accepting patients | H4: KOUBA, DAVID | I4: No | J4: 1073561866 | K4: Unknown | L4: Dermatology | M4: Dermatology | O4: No | R4: TOLEDO CLINIC DAVID KOUBA SOLE MBR | S4: 1136 COUNTRY CLUB RD UNIT C | T4: ADRIAN | U4: MI | V4: 49221-8209 | W4: TOLEDO CLINIC DAVID KOUBA SOLE MBR | X4: 45996.019 | Z4: =_xlfn.XLOOKUP(VALUE(LEFT(V4,5)), 'MI Zip Codes'!A:A, 'MI Zip Codes'!B:B, "County Not Found") -> Lenawee
A5: c957953d-ba9e-431c-b5a8-495aaf35800c | B5: jQ2Q9b/gaTvhToUkGyM5r1pVzNBwnBvPi7kR5jUwQUj0nfFmJw+oRAg+E0lj+C7WpnwlqyCEnKzTc5uSvhqLkg== | C5: 45899.865 | D5: CCN Region 2 | E5: Active | G5: Accepting patients | H5: KOUBA, DAVID | I5: No | J5: 1073561866 | K5: No | L5: Dermatology | M5: Dermatology | O5: No | P5: 517-366-5110 | Q5: 517-366-5115 | R5: TOLEDO CLINIC | S5: 1136 COUNTRY CLUB RD UNIT C | T5: ADRIAN | U5: MI | V5: 49221-8209 | W5: TOLEDO CLINIC | X5: 44884.404 | Z5: =_xlfn.XLOOKUP(VALUE(LEFT(V5,5)), 'MI Zip Codes'!A:A, 'MI Zip Codes'!B:B, "County Not Found") -> Lenawee
A6: 07944e46-e3f5-49cb-8497-0ee68f107c73 | B6: Ph0zmVuO6ijTATpU+g3CLDMgiowtySbxSH3U50JcXOW+wXqzD4cv0nl96/l/QRU0VNGAcU/P9qaxtT8fxvuOhg== | C6: 46019.279 | D6: CCN Region 2 | E6: Active | F6: No | G6: Accepting patients | H6: JAWORSKY, CHRISTINE | I6: No | J6: 1073592804 | K6: No | L6: Dermatology - Dermatopathology | M6: Dermatology | O6: No | P6: 419-534-3500 | Q6: 419-534-2608 | R6: CONSULTANTS IN LAB MEDTOLEDO | S6: 818 RIVERSIDE AVE | T6: ADRIAN | U6: MI | V6: 49221-1446 | W6: CONSULTANTS IN LAB MED TOLEDO | X6: 45415.012 | Z6: =_xlfn.XLOOKUP(VALUE(LEFT(V6,5)), 'MI Zip Codes'!A:A, 'MI Zip Codes'!B:B, "County Not Found") -> Lenawee
A7: 8e62484a-b763-45eb-b637-182147dd0ae0 | B7: Tzoy6Kd0EaERgCrlqQAwQs6yGUD/no8qdU5QkYkKkmHQWEASSNT7EZOYW8sEjAMN1fTd4e9XAf3jPJZFiMgeAg== | C7: 46051.882 | D7: CCN Region 2 | E7: Active | F7: No | G7: Accepting patients | H7: TOLEDO CLINIC | I7: No | J7: 1114079167 | K7: No | L7: Dermatology | M7: Dermatology | O7: No | P7: 517-366-5110 | Q7: 517-366-5115 | R7: TOLEDO CLINIC | S7: 1136 COUNTRY CLUB RD UNIT C | T7: ADRIAN | U7: MI | V7: 49221-8209 | X7: 45232.002 | Z7: =_xlfn.XLOOKUP(VALUE(LEFT(V7,5)), 'MI Zip Codes'!A:A, 'MI Zip Codes'!B:B, "County Not Found") -> Lenawee
A8: b5902d42-70dd-40ca-95c3-818e62fdf2b0 | B8: gWGad84sRpvJ7TsyeYpfwB4sqBrRMWnsB/PY04ukuqsG10jBhvG70YxzL2EvXYMU8ZunT9EItA3zexngVa5jNw== | C8: 46021.738 | D8: CCN Region 2 | E8: Active | G8: Accepting patients | H8: LAWRENCE J DESJARLAIS MD | I8: No | J8: 1306027073 | K8: No | L8: Dermatology | M8: Dermatology | P8: 517-264-5603 | Q8: 517-264-5708 | R8: LAWRENCE J DESJARLAIS MD | S8: 2000 CURTIS RD | T8: ADRIAN | U8: MI | V8: 49221-1778 | X8: 43854.335 | Z8: =_xlfn.XLOOKUP(VALUE(LEFT(V8,5)), 'MI Zip Codes'!A:A, 'MI Zip Codes'!B:B, "County Not Found") -> Lenawee
A9: 3a6a85b7-25af-4d75-ae50-2c689cdf9959 | B9: c9BbVj8axdB2u32jQnUMyw+k6HiUY4hXD1FzqLW8uDxUpettQDHhb2G6NTL4DISYC79VKMMypAsqoAWyoatZKg== | C9: 46000.691 | D9: CCN Region 2 | E9: Active | F9: No | G9: Accepting patients | H9: TOLEDO CLINIC DAVID KOUBA SOLE MBR | I9: No | J9: 1326538703 | K9: Unknown | L9: Dermatology | M9: Dermatology | O9: No | P9: 517-366-5110 | R9: TOLEDO CLINIC DAVID KOUBA SOLE MBR | S9: 1136 COUNTRY CLUB RD UNIT C | T9: ADRIAN | U9: MI | V9: 49221-8209 | X9: 45996.027 | Z9: =_xlfn.XLOOKUP(VALUE(LEFT(V9,5)), 'MI Zip Codes'!A:A, 'MI Zip Codes'!B:B, "County Not Found") -> Lenawee
A10: 0a9e3220-fcc8-488e-8384-401e3cd39cf3 | B10: mQUZMF2o3q9SE7bIDZXdyNyIgZE9BlRaSDkHguNX6JbqIDz56FE8tzkmYVYEbk1Rh0emKL84qiU/jRmorYmdwA== | C10: 46022.104 | D10: CCN Region 2 | E10: Active | G10: Accepting patients | H10: DESJARLAIS, LAWRENCE J | I10: No | J10: 1437116852 | K10: No | L10: Dermatology | M10: Dermatology | P10: 517-264-5603 | Q10: 517-264-5708 | R10: LAWRENCE J DESJARLAIS MD | S10: 2000 CURTIS RD | T10: ADRIAN | U10: MI | V10: 49221-1778 | W10: LAWRENCE J DESJARLAIS MD | X10: 43854.491 | Z10: =_xlfn.XLOOKUP(VALUE(LEFT(V10,5)), 'MI Zip Codes'!A:A, 'MI Zip Codes'!B:B, "County Not Found") -> Lenawee
A11: c297851a-aa3a-4b4e-95f1-d52c414df4b5 | B11: Y3h1SZk9UjFetFQ+Aw2+hRoJ/2UZdLjhYQEnY1hcwWcXAF7NlXCPMS39C/KYiYqtIw0kYoIEOaOy9BYcov0PRA== | C11: 46019.457 | D11: CCN Region 2 | E11: Active | F11: No | G11: Accepting patients | H11: ILYAS, MUNEEB | I11: No | J11: 1659876308 | K11: No | L11: Dermatology | M11: Dermatology | O11: No | P11: 419-473-3561 | R11: ADRIAN DERMASURGERY CENTER | S11: 1136 COUNTRY CLUB RD UNIT C | T11: ADRIAN | U11: MI | V11: 49221-8209 | W11: TOLEDO CLINIC DAVID KOUBA SOLE MBR | X11: 46010.09 | Z11: =_xlfn.XLOOKUP(VALUE(LEFT(V11,5)), 'MI Zip Codes'!A:A, 'MI Zip Codes'!B:B, "County Not Found") -> Lenawee
A12: c28076d1-8776-4e15-a746-a171d6cfee59 | B12: 9hOyvXdazTJdjfTMmyXc5725l28CZ5t9F+5y838qTnHtD6ExwaCuEmfIIWkQnoOSasgTqwF2KRMcW7urJi9qJQ== | C12: 46010.28 | D12: CCN Region 2 | E12: Active | F12: No | G12: Accepting patients | H12: TOLEDO CLINIC DAVID KOUBA SOLE MBR | I12: No | J12: 1700842796 | K12: Unknown | L12: Dermatology | M12: Dermatology | O12: No | P12: 419-473-3561 | R12: ADRIAN DERMASURGERY CENTER | S12: 1136 COUNTRY CLUB RD UNIT C | T12: ADRIAN | U12: MI | V12: 49221-8209 | X12: 46010.072 | Z12: =_xlfn.XLOOKUP(VALUE(LEFT(V12,5)), 'MI Zip Codes'!A:A, 'MI Zip Codes'!B:B, "County Not Found") -> Lenawee
A13: 6bd39877-9d24-4496-88cf-54bed4d36940 | B13: n1/IRVzRMyQslyqVoFGCRoHR1tBSmbD9udjjNB1UDCS1CA2dhPZiakfMcIkDtYp73zrjJu6tRP3SxLqOtGik3w== | C13: 45899.921 | D13: CCN Region 2 | E13: Active | F13: No | G13: Accepting patients | H13: WINFIELD, HARRY | I13: No | J13: 1922023670 | K13: Unknown | L13: Dermatology - Dermatopathology | M13: Dermatology | O13: No | P13: 419-534-3500 | Q13: 419-534-2608 | R13: CONSULTANTS IN LAB MEDTOLEDO | S13: 818 RIVERSIDE AVE | T13: ADRIAN | U13: MI | V13: 49221-1446 | W13: CONSULTANTS IN LAB MED TOLEDO | X13: 45415.013 | Z13: =_xlfn.XLOOKUP(VALUE(LEFT(V13,5)), 'MI Zip Codes'!A:A, 'MI Zip Codes'!B:B, "County Not Found") -> Lenawee
A14: 1ec3f9c1-0844-4bb6-8cd6-0dd0c7291bc6 | B14: KZbbQQR4Uu1vn+MK1yxBrD578zet3+Joxpiake7Hqc64G5cRAQhR+0tl0PnnlZVo2L1jSCpzrceedwxddjt69w== | C14: 45898.743 | D14: CCN Region 2 | E14: Active | F14: No | G14: Accepting patients | H14: CONSULTANTS IN LAB MED TOLEDO | I14: No | J14: 1982673372 | K14: Unknown | L14: Dermatology - Dermatopathology | M14: Dermatology | O14: No | P14: 419-534-3500 | Q14: 419-534-2608 | R14: CONSULTANTS IN LAB MEDTOLEDO | S14: 818 RIVERSIDE AVE | T14: ADRIAN | U14: MI | V14: 49221-1446 | X14: 45416.036 | Z14: =_xlfn.XLOOKUP(VALUE(LEFT(V14,5)), 'MI Zip Codes'!A:A, 'MI Zip Codes'!B:B, "County Not Found") -> Lenawee
A15: e7da7983-5e48-4352-a65e-fb9e96e78d2b | B15: bQt9ZkXFOixhqyw8u/RrjCfPRm4Z6uzDFzcbxVq0CeRebFkQXGfPnWGCtMvpzt/15rYNU0nUUu63o7h3Qt686g== | C15: 46169.612 | D15: CCN Region 2 | E15: Active | F15: No | G15: Accepting patients | H15: DERMATOLOGY SPECIALISTS OF GRAND RAPI | I15: No | J15: 1821972548 | K15: Unknown | L15: Dermatology | M15: Dermatology | O15: No | P15: 586-876-2345 | R15: DERMATOLOGY SPECIALISTS OF GRAND RAPIDS | S15: 1000 EAST PARIS AVE SE STE 104 | T15: GRAND RAPIDS | U15: MI | V15: 49546-3680 | X15: 46169.445 | Z15: =_xlfn.XLOOKUP(VALUE(LEFT(V15,5)), 'MI Zip Codes'!A:A, 'MI Zip Codes'!B:B, "County Not Found") -> Kent | AA15: Battle Creek
A16: e10343d3-0a5c-4f90-a632-8a3396330ba3 | B16: qr6dUvVbVMV3x0SSZ2A4JCZg4GFs1CqJLsaRJ2E6jF2G2oIw4YYKTgIsiwuEe/rtd525171GEYL32YEI6+5Z/g== | C16: 46094.228 | D16: CCN Region 2 | E16: Active | F16: No | G16: Accepting patients | H16: WMED HEALTH | I16: No | J16: 1316212343 | K16: No | L16: Dermatology | M16: Dermatology | O16: No | P16: 269-337-6500 | Q16: 269-337-6565 | R16: WESTERN MICHIGAN UNIVERSITY SCHOOL OF | S16: 1000 OAKLAND DR | T16: KALAMAZOO | U16: MI | V16: 49008-1282 | X16: 45213.718 | Z16: =_xlfn.XLOOKUP(VALUE(LEFT(V16,5)), 'MI Zip Codes'!A:A, 'MI Zip Codes'!B:B, "County Not Found") -> Kalamazoo | AA16: Battle Creek
A17: 9bff81a8-bd44-4de9-b188-68487dd923ee | B17: /O4Bh+ERK4ULEQ50fDanzMkqw3vGRmbD76Wr6kHP7BNOzsEYf7MYz+SkXwNwsdWyznk4UNwpsqAO3yQllfBq1Q== | C17: 45900.602 | D17: CCN Region 2 | E17: Active | G17: Accepting patients | H17: FOREFRONT DERMATOLOGY | I17: No | J17: 1003356692 | K17: Yes | L17: Dermatology | M17: Dermatology | O17: No | P17: 616-459-7122 | R17: FOREFRONT DERMATOLOGY | S17: 1005 W GREEN ST STE 200 | T17: HASTINGS | U17: MI | V17: 49058-1726 | X17: 44059.698 | Z17: =_xlfn.XLOOKUP(VALUE(LEFT(V17,5)), 'MI Zip Codes'!A:A, 'MI Zip Codes'!B:B, "County Not Found") -> Barry | AA17: Battle Creek
A18: 79c27c74-a395-4704-b04e-2aa7788920cd | B18: IZvtrS6+MhcdYWYQiq5lUwoSeinh545goFpUQcAaOi5h0Q8CPO/oqL99pJNZ6IP1ru4ix9y2qnySfcUbB5xDvA== | C18: 45899.653 | D18: CCN Region 2 | E18: Active | G18: Accepting patients | H18: MESSING, ROBYN | I18: No | J18: 1215019682 | K18: No | L18: Dermatology | M18: Dermatology | O18: No | P18: 517-627-2181 | Q18: 517-622-1242 | R18: FAMILY MEDICINE OF MICHIGAN | S18: 1035 CHARLEVOIX DR STE 100 | T18: GRAND LEDGE | U18: MI | V18: 48837-2223 | W18: SMITH | X18: 44162.061 | Z18: =_xlfn.XLOOKUP(VALUE(LEFT(V18,5)), 'MI Zip Codes'!A:A, 'MI Zip Codes'!B:B, "County Not Found") -> Eaton | AA18: Battle Creek
A19: 26cdefea-fff4-4e55-b5c2-3ddd945a07a8 | B19: N1OhtLXApEVB053Jp0DYbRMLSaOBi65okBQ8M431ZZ629ohwZPdJbs9VDK4h0yYCEYFOQc1r3wB+mPTpFGnMiA== | C19: 46030.554 | D19: CCN Region 2 | E19: Active | G19: Accepting patients | H19: COTTER, MURRAY | I19: No | J19: 1669598744 | K19: No | L19: Dermatology | M19: Dermatology | P19: 989-884-0139 | Q19: 989-356-6396 | R19: ADVANCED DERMATOLOGY OF MICHIGAN | S19: 105 ARBOR LN | T19: ALPENA | U19: MI | V19: 49707-1301 | W19: ADVANCED DERMATOLOGY OF MICHIGAN | X19: 43971.044 | Z19: =_xlfn.XLOOKUP(VALUE(LEFT(V19,5)), 'MI Zip Codes'!A:A, 'MI Zip Codes'!B:B, "County Not Found") -> Alpena
A20: 51555f60-735a-422f-8b63-205cb2d938e9 | B20: tjT2lmLFkiU9P7tgBd3Wi+JjsNOlHf1jN0xlYGGDz6RyeJZ+PO4bD8e5Rluck2AUSGykMTYeUYVaoN8HFXrAQg== | C20: 45898.806 | D20: CCN Region 2 | E20: Active | G20: Accepting patients | H20: ADVANCED DERMATOLOGY OF MICHIGAN | I20: No | J20: 1851708929 | K20: Unknown | L20: Dermatology | M20: Dermatology | P20: 989-884-0139 | Q20: 989-356-6396 | R20: ADVANCED DERMATOLOGY OF MICHIGAN | S20: 105 ARBOR LN | T20: ALPENA | U20: MI | V20: 49707-1301 | X20: 43915.38 | Z20: =_xlfn.XLOOKUP(VALUE(LEFT(V20,5)), 'MI Zip Codes'!A:A, 'MI Zip Codes'!B:B, "County Not Found") -> Alpena
A21: 00d2dd38-ddb3-4a71-9165-ea17790b75a3 | B21: zpBvjKD9VppI6bepw1Pj7dV5jiSNQshdEUh16E+WoeZ7U4bF3qAA9wVJKUB6YA92NWLMGXJBsXSsMNPy5+OE4Q== | C21: 45902.537 | D21: CCN Region 2 | E21: Active | G21: Accepting patients | H21: ADVANCED DERMATOLOGY OF MICHIGAN | I21: No | J21: 1851708929 | K21: Unknown | L21: Dermatology | M21: Dermatology | P21: 989-884-0139 | Q21: 989-356-6396 | R21: ADVANCED DERMATOLOGY OF MICHIGAN | S21: 105 ARBOR LANE | T21: ALPENA | U21: MI | V21: 49707-1301 | X21: 43915.38 | Z21: =_xlfn.XLOOKUP(VALUE(LEFT(V21,5)), 'MI Zip Codes'!A:A, 'MI Zip Codes'!B:B, "County Not Found") -> Alpena
A22: 06cfae30-68d3-4968-82da-2baa35ef224f | B22: nqQXGmLxmkkUyc5ztU9l1CmLjCL+j7T9HJTfHI96TYASZGx6hcKb9jQNBK1AvfV7TiMLwuDJDUNp0lzPzT7nKg== | C22: 45899.654 | D22: CCN Region 2 | E22: Active | F22: No | G22: Accepting patients | H22: REGENTS OF UNIVERSITY OF MICH | I22: No | J22: 1003848144 | K22: Unknown | L22: Dermatology - MOHS-Micrographic Surgery | M22: Dermatology | O22: No | P22: 734-936-4054 | Q22: 734-647-6593 | R22: REGENTS OF UNIVERSITY OF MICH | S22: 1500 E MED CTR DR FL B1 TAUBMAN | T22: ANN ARBOR | U22: MI | V22: 48109 | X22: 45241.161 | Z22: =_xlfn.XLOOKUP(VALUE(LEFT(V22,5)), 'MI Zip Codes'!A:A, 'MI Zip Codes'!B:B, "County Not Found") -> Washtenaw
A23: ccd6de6e-5524-42a0-92ec-7d2f547ec2fc | B23: pPJSQW/VMckDSsRj5quY7TSeDpwZo2OLiQSi/mNqtzIqPUhB0B5t2utJJKnC+JoM2a0WvdJUAXZoHdxnPt72dg== | C23: 45900.65 | D23: CCN Region 2 | E23: Active | F23: No | G23: Accepting patients | H23: REGENTS OF UNIVERSITY OF MICH | I23: No | J23: 1003848144 | K23: Unknown | L23: Dermatology - Procedural Dermatology | M23: Dermatology | O23: No | P23: 734-936-4054 | Q23: 734-647-6593 | R23: REGENTS OF UNIVERSITY OF MICH | S23: 1500 E MED CTR DR FL B1 TAUBMAN | T23: ANN ARBOR | U23: MI | V23: 48109 | X23: 45241.161 | Z23: =_xlfn.XLOOKUP(VALUE(LEFT(V23,5)), 'MI Zip Codes'!A:A, 'MI Zip Codes'!B:B, "County Not Found") -> Washtenaw
A24: 9ba974a3-d3c2-424f-a84c-f727506e67a4 | B24: D5APO8E3Od8uTyvQ1Kk0bao//XzrCKCheq5WOPyRSOl/SAG8s/N8WzQICVCbVvbFj2VpSGNxHIOoxifXA2zpdA== | C24: 45902.601 | D24: CCN Region 2 | E24: Active | F24: No | G24: Accepting patients | H24: REGENTS OF UNIVERSITY OF MICH | I24: No | J24: 1003848144 | K24: Unknown | L24: Dermatology | M24: Dermatology | O24: No | P24: 734-936-4054 | Q24: 734-647-6593 | R24: REGENTS OF UNIVERSITY OF MICH | S24: 1500 E MED CTR DR FL B1 TAUBMAN | T24: ANN ARBOR | U24: MI | V24: 48109 | X24: 45241.161 | Z24: =_xlfn.XLOOKUP(VALUE(LEFT(V24,5)), 'MI Zip Codes'!A:A, 'MI Zip Codes'!B:B, "County Not Found") -> Washtenaw
A25: 06fb75d4-6a9b-4c56-85c4-42c9de7db75f | B25: lD9Qw/kLqxjJpllUPj+tj1T5tNLpbdrWObf3lqYO663Sm5KkJDslyI5AZQY2o+XSE3LI/MttdS5x6cX7EaFddQ== | C25: 46194.183 | D25: CCN Region 2 | E25: Active | G25: Accepting patients | H25: RAMIREZ, JAMES | I25: No | J25: 1003867946 | K25: No | L25: Pathology - Dermatopathology | M25: Dermatology | O25: No | P25: 248-360-5881 | R25: ST JOSEPH MERCY HOSPITAL | S25: 5301 E HURON RIVER DR | T25: ANN ARBOR | U25: MI | V25: 48106 | W25: ST JOSEPH MERCY HOSPITAL | X25: 44072.193 | Z25: =_xlfn.XLOOKUP(VALUE(LEFT(V25,5)), 'MI Zip Codes'!A:A, 'MI Zip Codes'!B:B, "County Not Found") -> Washtenaw
A26: a58fe9e1-2bdd-4e94-8586-026c58e58207 | B26: b1WBuMoErNuOMVvfztZFkeQgXduDPiBYs3YsC9VrfRTIj1Na+zb7DpipgMF2sd6M7cFWaIgO7kyhYplw28qRGw== | C26: 46182.68 | D26: CCN Region 2 | E26: Active | F26: No | G26: Accepting patients | H26: REGENTS OF THE UNIVERSITY OF MICHIGAN | I26: Yes | J26: 1003878539 | K26: Unknown | L26: Dermatology | M26: Dermatology | O26: No | P26: 734-936-4054 | Q26: 734-647-6593 | R26: REGENTS OF UNIVERSITY OF MICH | S26: 1500 E MEDICAL CENTER DR FL 1 | T26: ANN ARBOR | U26: MI | V26: 48109-5000 | X26: 45543.071 | Z26: =_xlfn.XLOOKUP(VALUE(LEFT(V26,5)), 'MI Zip Codes'!A:A, 'MI Zip Codes'!B:B, "County Not Found") -> Washtenaw
A27: 91134781-62ad-4a67-88a4-1f37b31801bd | B27: 8BaS5BTl20o13vyPHIz5sGjnqg96AmdmDrcsPWeGIVZuK9FuoIWtNvvjf4dyS0D8kdx5cpEUCzVcsTzvUbelnQ== | C27: 46182.68 | D27: CCN Region 2 | E27: Active | F27: No | G27: Accepting patients | H27: REGENTS OF THE UNIVERSITY OF MICHIGAN | I27: Yes | J27: 1003878539 | K27: Unknown | L27: Dermatology - Procedural Dermatology | M27: Dermatology | O27: No | P27: 734-936-4054 | R27: REGENTS OF UNIVERSITY OF MICH | S27: 1500 E MED CTR DR FL 1 RECP B | T27: ANN ARBOR | U27: MI | V27: 48109 | X27: 45858.02 | Z27: =_xlfn.XLOOKUP(VALUE(LEFT(V27,5)), 'MI Zip Codes'!A:A, 'MI Zip Codes'!B:B, "County Not Found") -> Washtenaw
A28: 19201116-84b6-489e-9941-2f223a62fd3d | B28: 2DfVp9r++7Csxd4FBgxrq9aNXHQjiXSJBd+W4qXdN0BdBzIk3FSZsaA4kL5Y0uWZZltls5ERq+mkvivNmpejuQ== | C28: 46182.68 | D28: CCN Region 2 | E28: Active | F28: No | G28: Accepting patients | H28: REGENTS OF THE UNIVERSITY OF MICHIGAN | I28: Yes | J28: 1003878539 | K28: Unknown | L28: Dermatology - Procedural Dermatology | M28: Dermatology | O28: No | P28: 734-936-6000 | R28: REGENTS OF UNIVERSITY OF MICH | S28: 1500 E MEDICAL CENTER DR FL 1 CANCER CTR | T28: ANN ARBOR | U28: MI | V28: 48109-5000 | X28: 45543.07 | Z28: =_xlfn.XLOOKUP(VALUE(LEFT(V28,5)), 'MI Zip Codes'!A:A, 'MI Zip Codes'!B:B, "County Not Found") -> Washtenaw
A29: 136948c7-dd3e-440a-b4b3-5a6b659a9430 | B29: yj1hMPydwW8bLKO42dmUbcjXtC+jjiTP8obcpV2kS13Hk1ALbBM/bs2Tc6GQQBw14HzRKwtPwA1ApYLjbCS3Uw== | C29: 46182.68 | D29: CCN Region 2 | E29: Active | F29: No | G29: Accepting patients | H29: REGENTS OF THE UNIVERSITY OF MICHIGAN | I29: Yes | J29: 1003878539 | K29: Unknown | L29: Dermatology - MOHS-Micrographic Surgery | M29: Dermatology | O29: No | P29: 734-936-6000 | R29: REGENTS OF UNIVERSITY OF MICH | S29: 1500 E MEDICAL CENTER DR FL 1 CANCER CTR | T29: ANN ARBOR | U29: MI | V29: 48109-5000 | X29: 45543.07 | Z29: =_xlfn.XLOOKUP(VALUE(LEFT(V29,5)), 'MI Zip Codes'!A:A, 'MI Zip Codes'!B:B, "County Not Found") -> Washtenaw
A30: 7b3e841b-07d0-4992-b35a-620e3a9a9d2c | B30: hxAkPZBnL0am9U1qWk/tBV1SOOu0fqE6jYErIgKTnk1n3vFWSL8aWWlsKFO8yDctMX4BRrW8aMpmdLHkQ9KdBQ== | C30: 46182.68 | D30: CCN Region 2 | E30: Active | F30: No | G30: Accepting patients | H30: REGENTS OF THE UNIVERSITY OF MICHIGAN | I30: Yes | J30: 1003878539 | K30: Unknown | L30: Dermatology | M30: Dermatology | O30: No | P30: 734-936-4054 | R30: REGENTS OF UNIVERSITY OF MICH | S30: 24 FRANK LLOYD WRIGHT DR # H2350 | T30: ANN ARBOR | U30: MI | V30: 48105-9484 | X30: 45543.071 | Z30: =_xlfn.XLOOKUP(VALUE(LEFT(V30,5)), 'MI Zip Codes'!A:A, 'MI Zip Codes'!B:B, "County Not Found") -> Washtenaw
A31: 82898a99-9305-4fbf-9780-6b8d04d426d9 | B31: DuwZPCKBfOOBMgYgA1aKIahhEhOzVPI3pe79mo5Wwd8T3qc+tFD57+ITqls56P4LgFg3RvmW90M+x4QFXbLFwg== | C31: 46182.68 | D31: CCN Region 2 | E31: Active | F31: No | G31: Accepting patients | H31: REGENTS OF THE UNIVERSITY OF MICHIGAN | I31: Yes | J31: 1003878539 | K31: Unknown | L31: Dermatology - MOHS-Micrographic Surgery | M31: Dermatology | O31: No | P31: 734-936-4054 | R31: REGENTS OF UNIVERSITY OF MICH | S31: 1500 E MED CTR DR FL 1 RECP B | T31: ANN ARBOR | U31: MI | V31: 48109 | X31: 45858.02 | Z31: =_xlfn.XLOOKUP(VALUE(LEFT(V31,5)), 'MI Zip Codes'!A:A, 'MI Zip Codes'!B:B, "County Not Found") -> Washtenaw
A32: 84ebf9dd-08d6-4f2e-8512-7c7b941e8cab | B32: KznFVNe7+yEQ4JkZQkGHCuPmEPCFD575iIFUNWxJYgLzcDFjsax3MZbF8RTr73cik5D35lKsRUz2JrgeO2VL5Q== | C32: 46182.68 | D32: CCN Region 2 | E32: Active | F32: No | G32: Accepting patients | H32: REGENTS OF THE UNIVERSITY OF MICHIGAN | I32: Yes | J32: 1003878539 | K32: Unknown | L32: Dermatology | M32: Dermatology | O32: No | P32: 734-936-6000 | R32: REGENTS OF UNIVERSITY OF MICH | S32: 1500 E MEDICAL CENTER DR FL 1 CANCER CTR | T32: ANN ARBOR | U32: MI | V32: 48109-5000 | X32: 45543.07 | Z32: =_xlfn.XLOOKUP(VALUE(LEFT(V32,5)), 'MI Zip Codes'!A:A, 'MI Zip Codes'!B:B, "County Not Found") -> Washtenaw
A33: e9e99985-7329-44c7-b5b9-845e7b83596a | B33: GASWHVZAJGIjCoj9RLw7A9swjps18r5EmO/UiQ+JFgVoB0Ux0ZSsL1JnqFCga1OqyA+Xl2A39IAg69sB+HFw5g== | C33: 46182.68 | D33: CCN Region 2 | E33: Active | F33: No | G33: Accepting patients | H33: REGENTS OF THE UNIVERSITY OF MICHIGAN | I33: Yes | J33: 1003878539 | K33: Unknown | L33: Dermatology | M33: Dermatology | O33: No | P33: 734-936-4054 | R33: REGENTS OF UNIVERSITY OF MICH | S33: 1500 E MED CTR DR 8TH FL CS MOTT | T33: ANN ARBOR | U33: MI | V33: 48109 | X33: 45543.07 | Z33: =_xlfn.XLOOKUP(VALUE(LEFT(V33,5)), 'MI Zip Codes'!A:A, 'MI Zip Codes'!B:B, "County Not Found") -> Washtenaw
A34: 6179cdcd-f147-43bf-801f-8fefefa88c36 | B34: /t1c9YZU+uvNJ8dpkoJ6YclGSLNQjYzqXGjGh/rU1u8n+O5qGHg6dfgMIjMsx4IbWcS5nyV//buTSObQE4RE+w== | C34: 46182.68 | D34: CCN Region 2 | E34: Active | F34: No | G34: Accepting patients | H34: REGENTS OF THE UNIVERSITY OF MICHIGAN | I34: Yes | J34: 1003878539 | K34: Unknown | L34: Dermatology | M34: Dermatology | O34: No | P34: 734-936-5900 | R34: REGENTS OF UNIVERSITY OF MICH | S34: 1500 E MEDICAL CENTER DR FL B1 | T34: ANN ARBOR | U34: MI | V34: 48109-5000 | X34: 45543.071 | Z34: =_xlfn.XLOOKUP(VALUE(LEFT(V34,5)), 'MI Zip Codes'!A:A, 'MI Zip Codes'!B:B, "County Not Found") -> Washtenaw
A35: dfabc2c9-4e3e-48f0-8f8e-aa89234fd926 | B35: VRMtBN+cwijDegrpqE4Ak+zl3RJ3zpsRITVqUsQVT9xSAZWr2tyCGK9oLRdWg4xSAELuO49bHaQilYMdaDruiA== | C35: 46182.68 | D35: CCN Region 2 | E35: Active | F35: No | G35: Accepting patients | H35: REGENTS OF THE UNIVERSITY OF MICHIGAN | I35: Yes | J35: 1003878539 | K35: Unknown | L35: Dermatology | M35: Dermatology | O35: No | P35: 734-936-4054 | R35: REGENTS OF UNIVERSITY OF MICH | S35: 1500 E MED CTR DR FL 1 RECP B | T35: ANN ARBOR | U35: MI | V35: 48109 | X35: 45858.02 | Z35: =_xlfn.XLOOKUP(VALUE(LEFT(V35,5)), 'MI Zip Codes'!A:A, 'MI Zip Codes'!B:B, "County Not Found") -> Washtenaw
A36: a93013b7-7e93-432e-9f5c-b00ae45cbf67 | B36: cO/4vwPKnzK9lXlhEge1rYPWJl20Ibgz9a/q8TsFni/xbA2TkAp1cqz61GNC9ncqAYGFlRepaffCcoVpvJASSQ== | C36: 46182.68 | D36: CCN Region 2 | E36: Active | F36: No | G36: Accepting patients | H36: REGENTS OF THE UNIVERSITY OF MICHIGAN | I36: Yes | J36: 1003878539 | K36: Unknown | L36: Dermatology | M36: Dermatology | O36: No | P36: 734-936-4054 | R36: REGENTS OF UNIVERSITY OF MICH | S36: 24 FRANK LLOYD WRIGHT DR # 2350 | T36: ANN ARBOR | U36: MI | V36: 48105-9484 | X36: 45543.07 | Z36: =_xlfn.XLOOKUP(VALUE(LEFT(V36,5)), 'MI Zip Codes'!A:A, 'MI Zip Codes'!B:B, "County Not Found") -> Washtenaw
A37: e6b8686e-6220-4957-b07b-b8e053ff272f | B37: t+6DDDkNVSM21FfjwtE6NfPu5I6GaEmJVi0G3bXLPrYp9ws4pXSkuaTegv+38pb/Zr0CY4yS6OoOWE80oJdWPw== | C37: 46182.68 | D37: CCN Region 2 | E37: Active | F37: No | G37: Accepting patients | H37: REGENTS OF THE UNIVERSITY OF MICHIGAN | I37: Yes | J37: 1003878539 | K37: Unknown | L37: Dermatology | M37: Dermatology | O37: No | P37: 734-936-4054 | R37: REGENTS OF UNIVERSITY OF MICH | S37: 24 FRANK LLOYD WRIGHT DR # H2300 | T37: ANN ARBOR | U37: MI | V37: 48105-9484 | X37: 45543.071 | Z37: =_xlfn.XLOOKUP(VALUE(LEFT(V37,5)), 'MI Zip Codes'!A:A, 'MI Zip Codes'!B:B, "County Not Found") -> Washtenaw
A38: 5d05d982-1250-45ff-9d70-d7e6fe11bdce | B38: 1sAz1AtvNj14/9zrmxhC62Wm6TqYIGMkMi9BlDrIGzd5Jhq22kKUvqjoBVUmSIeCNP5lT9IkOIbpdmLf6k6mjw== | C38: 46182.68 | D38: CCN Region 2 | E38: Active | F38: No | G38: Accepting patients | H38: REGENTS OF THE UNIVERSITY OF MICHIGAN | I38: Yes | J38: 1003878539 | K38: Unknown | L38: Dermatology | M38: Dermatology | O38: No | P38: 734-763-9142 | R38: REGENTS OF UNIVERSITY OF MICH | S38: 1500 E MED CTR FL B1 TAUBMAN | T38: ANN ARBOR | U38: MI | V38: 48109 | X38: 45543.07 | Z38: =_xlfn.XLOOKUP(VALUE(LEFT(V38,5)), 'MI Zip Codes'!A:A, 'MI Zip Codes'!B:B, "County Not Found") -> Washtenaw
A39: 6895d054-e33f-48f0-87eb-1c2aa434f626 | B39: Txz84Mk13fBXWq9VItk29Bq+HmuieWdscJZTmNqkS4zJnLQPNwf0tyz2SrJ218GUY7YR6ZuN52Z25E7c9TVPww== | C39: 45898.793 | D39: CCN Region 2 | E39: Active | G39: Accepting patients | H39: HELFRICH, YOLANDA | I39: No | J39: 1003903873 | K39: Unknown | L39: Dermatology | M39: Dermatology | O39: No | P39: 734-998-7400 | R39: REGENTS OF UNIVERSITY OF MICH | S39: 24 FRANK LLOYD WRIGHT DR | T39: ANN ARBOR | U39: MI | V39: 48105-9484 | W39: REGENTS OF UNIV OF MICH | X39: 44364.015 | Z39: =_xlfn.XLOOKUP(VALUE(LEFT(V39,5)), 'MI Zip Codes'!A:A, 'MI Zip Codes'!B:B, "County Not Found") -> Washtenaw
A40: 37e10387-e980-4f1e-9fe7-205dad94b992 | B40: U2rlREHwyao6nZgtkQ85kso+57xaTPVUGxPZwLfZJ3+f8r0J0hQG7/KkL5Njk1EAQsDnU8l85YTukfctPXDk/Q== | C40: 46113.192 | D40: CCN Region 2 | E40: Active | G40: Accepting patients | H40: HELFRICH, YOLANDA | I40: No | J40: 1003903873 | K40: No | L40: Dermatology | M40: Dermatology | O40: No | P40: 734-998-7400 | R40: REGENTS OF UNIVERSITY OF MICH | S40: 24 FRANK LLOYD WRIGHT DR | T40: ANN ARBOR | U40: MI | V40: 48105-9484 | W40: REGENTS OF UNIVERSITY OF MICH | X40: 44405.217 | Z40: =_xlfn.XLOOKUP(VALUE(LEFT(V40,5)), 'MI Zip Codes'!A:A, 'MI Zip Codes'!B:B, "County Not Found") -> Washtenaw
...

Sheet MI Zip Codes
A1: ZIP Code | B1: County
A2: 48001 | B2: St. Clair
A3: 48002 | B3: St. Clair
A4: 48003 | B4: St. Clair
A5: 48004 | B5: St. Clair
A6: 48005 | B6: Macomb
A7: 48006 | B7: St. Clair
A8: 48007 | B8: Macomb
A9: 48009 | B9: Oakland
A10: 48012 | B10: Oakland
A11: 48014 | B11: Macomb
A12: 48015 | B12: Macomb
A13: 48017 | B13: Macomb
... A1162: 49971 | B1162: Gogebic

Sheet hiddenSheet
A1: ppms_providerservice:ChxXBc3b+Fd0KATrqGxf6awwVSYZI3pupJSuKmstFwrhmyX+U7NlzdtMlVQv5yQ3kLhUq3ujd47Gf5RvmGXVrg==:ppms_providerserviceid=%28Do%20Not%20Modify%29%20Provider%20Service&checksumLogicalName=%28Do%20Not%20Modify%29%20Row%20Checksum&modifiedon=%28Do%20Not%20Modify%29%20Modified%20On&ppms_networknametext=Network%20Name&statuscode=Status&ppms_vss=VSS&ppms_availability=Availability&ppms_providerid=Provider&6bda24be-3f20-4656-ba57-a8aeaaaa4c24.ppms_notesavailable=Notes%20%28Provider%29%20%28Provider%29&ppms_provideridentifer=Provider%20Identifier&ppms_highperformingprovider=HPP&ppms_specialty=Specialty&172b72a4-3029-42fc-b185-2eb5ca00a4bc.ppms_specialtygroup=Specialty%20Group%20%28Specialty%29%20%28Specialty%29&ppms_subservicerollup=Subservice%20Rollup&ppms_telehealthavailable=Telehealth%20Available&ppms_caresitephonenumber=Care%20Site%20Phone%20Number&dd321304-1362-46e3-8699-8688a1353fa1.ppms_caresitefax=Care%20Site%20Fax%20%28Caresite%29%20%28Care%20Site%29&ppms_caresite=Caresite&ppms_caresiteaddress=Care%20Site%20Address&ppms_caresitecity=Care%20Site%20City&ppms_caresitestateprovince=Care%20Site%20State&ppms_caresitezipcode=Care%20Site%20Zip%20Code&ppms_organization=Organization%20%2f%20Group&createdon=Created%20On&ppms_deactivationdate=Deactivation%20Date&ppms_coveragecounty=Coverage%20County
A2: Active | B2: Pending | C2: Inactive | D2: Address Validation Failure | E2: Provider Inactive | F2: Marked for Deletion
A3: No | B3: Yes
A4: Accepting patients | B4: Not accepting new patients | C4: Not taking veterans | D4: Not taking patients for billing reasons | E4: No availability | F4: Asked to be removed from the network
A5: No | B5: Yes
A6: Unknown | B6: Yes | C6: No
A7: No | B7: Yes
